[2025-07-08T05:15:47.839+0000] {local_task_job_runner.py:123} INFO - ::group::Pre task execution logs
[2025-07-08T05:15:47.900+0000] {taskinstance.py:2612} INFO - Dependencies all met for dep_context=non-requeueable deps ti=<TaskInstance: extract_raw_data_pipeline.extract_raw_data manual__2025-07-08T05:15:44.200757+00:00 [queued]>
[2025-07-08T05:15:47.927+0000] {taskinstance.py:2612} INFO - Dependencies all met for dep_context=requeueable deps ti=<TaskInstance: extract_raw_data_pipeline.extract_raw_data manual__2025-07-08T05:15:44.200757+00:00 [queued]>
[2025-07-08T05:15:47.929+0000] {taskinstance.py:2865} INFO - Starting attempt 1 of 1
[2025-07-08T05:15:47.984+0000] {taskinstance.py:2888} INFO - Executing <Task(PythonOperator): extract_raw_data> on 2025-07-08 05:15:44.200757+00:00
[2025-07-08T05:15:48.024+0000] {warnings.py:112} WARNING - /home/***/.local/lib/python3.12/site-packages/***/task/task_runner/standard_task_runner.py:70: DeprecationWarning: This process (pid=649) is multi-threaded, use of fork() may lead to deadlocks in the child.
  pid = os.fork()

[2025-07-08T05:15:48.033+0000] {standard_task_runner.py:72} INFO - Started process 652 to run task
[2025-07-08T05:15:48.031+0000] {standard_task_runner.py:104} INFO - Running: ['***', 'tasks', 'run', 'extract_raw_data_pipeline', 'extract_raw_data', 'manual__2025-07-08T05:15:44.200757+00:00', '--job-id', '31', '--raw', '--subdir', 'DAGS_FOLDER/driven_data_pipeline.py', '--cfg-path', '/tmp/tmp2s05c26x']
[2025-07-08T05:15:48.036+0000] {standard_task_runner.py:105} INFO - Job 31: Subtask extract_raw_data
[2025-07-08T05:15:48.889+0000] {task_command.py:467} INFO - Running <TaskInstance: extract_raw_data_pipeline.extract_raw_data manual__2025-07-08T05:15:44.200757+00:00 [running]> on host 5e24963c1987
[2025-07-08T05:15:55.835+0000] {taskinstance.py:3131} INFO - Exporting env vars: AIRFLOW_CTX_DAG_OWNER='***' AIRFLOW_CTX_DAG_ID='extract_raw_data_pipeline' AIRFLOW_CTX_TASK_ID='extract_raw_data' AIRFLOW_CTX_EXECUTION_DATE='2025-07-08T05:15:44.200757+00:00' AIRFLOW_CTX_TRY_NUMBER='1' AIRFLOW_CTX_DAG_RUN_ID='manual__2025-07-08T05:15:44.200757+00:00'
[2025-07-08T05:15:55.842+0000] {taskinstance.py:731} INFO - ::endgroup::
[2025-07-08T05:15:55.938+0000] {driven_data_pipeline.py:148} INFO - Started batch processing for 2025-07-08.
[2025-07-08T05:15:55.940+0000] {driven_data_pipeline.py:34} INFO - Created synthetic data for MX country code.
[2025-07-08T05:15:57.376+0000] {driven_data_pipeline.py:100} INFO - Written 551 records to the CSV file.
[2025-07-08T05:15:58.055+0000] {driven_data_pipeline.py:121} INFO - Added UUID to the dataset.
[2025-07-08T05:15:58.118+0000] {taskinstance.py:3310} ERROR - Task failed with exception
Traceback (most recent call last):
  File "/home/airflow/.local/lib/python3.12/site-packages/airflow/models/taskinstance.py", line 767, in _execute_task
    result = _execute_callable(context=context, **execute_callable_kwargs)
             ^^^^^^^^^^^^^^^^^^^^^^^^^^^^^^^^^^^^^^^^^^^^^^^^^^^^^^^^^^^^^
  File "/home/airflow/.local/lib/python3.12/site-packages/airflow/models/taskinstance.py", line 733, in _execute_callable
    return ExecutionCallableRunner(
           ^^^^^^^^^^^^^^^^^^^^^^^^
  File "/home/airflow/.local/lib/python3.12/site-packages/airflow/utils/operator_helpers.py", line 252, in run
    return self.func(*args, **kwargs)
           ^^^^^^^^^^^^^^^^^^^^^^^^^^
  File "/home/airflow/.local/lib/python3.12/site-packages/airflow/models/baseoperator.py", line 406, in wrapper
    return func(self, *args, **kwargs)
           ^^^^^^^^^^^^^^^^^^^^^^^^^^^
  File "/home/airflow/.local/lib/python3.12/site-packages/airflow/operators/python.py", line 238, in execute
    return_value = self.execute_callable()
                   ^^^^^^^^^^^^^^^^^^^^^^^
  File "/home/airflow/.local/lib/python3.12/site-packages/airflow/operators/python.py", line 256, in execute_callable
    return runner.run(*self.op_args, **self.op_kwargs)
           ^^^^^^^^^^^^^^^^^^^^^^^^^^^^^^^^^^^^^^^^^^^
  File "/home/airflow/.local/lib/python3.12/site-packages/airflow/utils/operator_helpers.py", line 252, in run
    return self.func(*args, **kwargs)
           ^^^^^^^^^^^^^^^^^^^^^^^^^^
  File "/opt/airflow/dags/driven_data_pipeline.py", line 154, in save_raw_data
    _update_datetime()
  File "/opt/airflow/dags/driven_data_pipeline.py", line 134, in _update_datetime
    df = pl.read_csv("/opt/airflow/data/raw_data.csv")
         ^^^^^^^^^^^^^^^^^^^^^^^^^^^^^^^^^^^^^^^^^^^^^
  File "/home/airflow/.local/lib/python3.12/site-packages/polars/_utils/deprecation.py", line 91, in wrapper
    return function(*args, **kwargs)
           ^^^^^^^^^^^^^^^^^^^^^^^^^
  File "/home/airflow/.local/lib/python3.12/site-packages/polars/_utils/deprecation.py", line 91, in wrapper
    return function(*args, **kwargs)
           ^^^^^^^^^^^^^^^^^^^^^^^^^
  File "/home/airflow/.local/lib/python3.12/site-packages/polars/_utils/deprecation.py", line 91, in wrapper
    return function(*args, **kwargs)
           ^^^^^^^^^^^^^^^^^^^^^^^^^
  File "/home/airflow/.local/lib/python3.12/site-packages/polars/io/csv/functions.py", line 500, in read_csv
    df = _read_csv_impl(
         ^^^^^^^^^^^^^^^
  File "/home/airflow/.local/lib/python3.12/site-packages/polars/io/csv/functions.py", line 646, in _read_csv_impl
    pydf = PyDataFrame.read_csv(
           ^^^^^^^^^^^^^^^^^^^^^
polars.exceptions.ComputeError: could not parse `personal_number` as dtype `i64` at column 'personal_number' (column number 4)

The current offset in the file is 1281255 bytes.

You might want to try:
- increasing `infer_schema_length` (e.g. `infer_schema_length=10000`),
- specifying correct dtype with the `dtypes` argument
- setting `ignore_errors` to `True`,
- adding `personal_number` to the `null_values` list.

Original error: ```remaining bytes non-empty```
[2025-07-08T05:15:58.194+0000] {taskinstance.py:1225} INFO - Marking task as FAILED. dag_id=extract_raw_data_pipeline, task_id=extract_raw_data, run_id=manual__2025-07-08T05:15:44.200757+00:00, execution_date=20250708T051544, start_date=20250708T051547, end_date=20250708T051558
[2025-07-08T05:15:58.262+0000] {taskinstance.py:340} INFO - ::group::Post task execution logs
[2025-07-08T05:15:58.265+0000] {standard_task_runner.py:124} ERROR - Failed to execute job 31 for task extract_raw_data (could not parse `personal_number` as dtype `i64` at column 'personal_number' (column number 4)

The current offset in the file is 1281255 bytes.

You might want to try:
- increasing `infer_schema_length` (e.g. `infer_schema_length=10000`),
- specifying correct dtype with the `dtypes` argument
- setting `ignore_errors` to `True`,
- adding `personal_number` to the `null_values` list.

Original error: ```remaining bytes non-empty```; 652)
Traceback (most recent call last):
  File "/home/airflow/.local/lib/python3.12/site-packages/airflow/task/task_runner/standard_task_runner.py", line 117, in _start_by_fork
    ret = args.func(args, dag=self.dag)
          ^^^^^^^^^^^^^^^^^^^^^^^^^^^^^
  File "/home/airflow/.local/lib/python3.12/site-packages/airflow/cli/cli_config.py", line 49, in command
    return func(*args, **kwargs)
           ^^^^^^^^^^^^^^^^^^^^^
  File "/home/airflow/.local/lib/python3.12/site-packages/airflow/utils/cli.py", line 115, in wrapper
    return f(*args, **kwargs)
           ^^^^^^^^^^^^^^^^^^
  File "/home/airflow/.local/lib/python3.12/site-packages/airflow/cli/commands/task_command.py", line 483, in task_run
    task_return_code = _run_task_by_selected_method(args, _dag, ti)
                       ^^^^^^^^^^^^^^^^^^^^^^^^^^^^^^^^^^^^^^^^^^^^
  File "/home/airflow/.local/lib/python3.12/site-packages/airflow/cli/commands/task_command.py", line 256, in _run_task_by_selected_method
    return _run_raw_task(args, ti)
           ^^^^^^^^^^^^^^^^^^^^^^^
  File "/home/airflow/.local/lib/python3.12/site-packages/airflow/cli/commands/task_command.py", line 341, in _run_raw_task
    return ti._run_raw_task(
           ^^^^^^^^^^^^^^^^^
  File "/home/airflow/.local/lib/python3.12/site-packages/airflow/utils/session.py", line 97, in wrapper
    return func(*args, session=session, **kwargs)
           ^^^^^^^^^^^^^^^^^^^^^^^^^^^^^^^^^^^^^^
  File "/home/airflow/.local/lib/python3.12/site-packages/airflow/models/taskinstance.py", line 3004, in _run_raw_task
    return _run_raw_task(
           ^^^^^^^^^^^^^^
  File "/home/airflow/.local/lib/python3.12/site-packages/airflow/models/taskinstance.py", line 273, in _run_raw_task
    TaskInstance._execute_task_with_callbacks(
  File "/home/airflow/.local/lib/python3.12/site-packages/airflow/models/taskinstance.py", line 3158, in _execute_task_with_callbacks
    result = self._execute_task(context, task_orig)
             ^^^^^^^^^^^^^^^^^^^^^^^^^^^^^^^^^^^^^^
  File "/home/airflow/.local/lib/python3.12/site-packages/airflow/models/taskinstance.py", line 3182, in _execute_task
    return _execute_task(self, context, task_orig)
           ^^^^^^^^^^^^^^^^^^^^^^^^^^^^^^^^^^^^^^^
  File "/home/airflow/.local/lib/python3.12/site-packages/airflow/models/taskinstance.py", line 767, in _execute_task
    result = _execute_callable(context=context, **execute_callable_kwargs)
             ^^^^^^^^^^^^^^^^^^^^^^^^^^^^^^^^^^^^^^^^^^^^^^^^^^^^^^^^^^^^^
  File "/home/airflow/.local/lib/python3.12/site-packages/airflow/models/taskinstance.py", line 733, in _execute_callable
    return ExecutionCallableRunner(
           ^^^^^^^^^^^^^^^^^^^^^^^^
  File "/home/airflow/.local/lib/python3.12/site-packages/airflow/utils/operator_helpers.py", line 252, in run
    return self.func(*args, **kwargs)
           ^^^^^^^^^^^^^^^^^^^^^^^^^^
  File "/home/airflow/.local/lib/python3.12/site-packages/airflow/models/baseoperator.py", line 406, in wrapper
    return func(self, *args, **kwargs)
           ^^^^^^^^^^^^^^^^^^^^^^^^^^^
  File "/home/airflow/.local/lib/python3.12/site-packages/airflow/operators/python.py", line 238, in execute
    return_value = self.execute_callable()
                   ^^^^^^^^^^^^^^^^^^^^^^^
  File "/home/airflow/.local/lib/python3.12/site-packages/airflow/operators/python.py", line 256, in execute_callable
    return runner.run(*self.op_args, **self.op_kwargs)
           ^^^^^^^^^^^^^^^^^^^^^^^^^^^^^^^^^^^^^^^^^^^
  File "/home/airflow/.local/lib/python3.12/site-packages/airflow/utils/operator_helpers.py", line 252, in run
    return self.func(*args, **kwargs)
           ^^^^^^^^^^^^^^^^^^^^^^^^^^
  File "/opt/airflow/dags/driven_data_pipeline.py", line 154, in save_raw_data
    _update_datetime()
  File "/opt/airflow/dags/driven_data_pipeline.py", line 134, in _update_datetime
    df = pl.read_csv("/opt/airflow/data/raw_data.csv")
         ^^^^^^^^^^^^^^^^^^^^^^^^^^^^^^^^^^^^^^^^^^^^^
  File "/home/airflow/.local/lib/python3.12/site-packages/polars/_utils/deprecation.py", line 91, in wrapper
    return function(*args, **kwargs)
           ^^^^^^^^^^^^^^^^^^^^^^^^^
  File "/home/airflow/.local/lib/python3.12/site-packages/polars/_utils/deprecation.py", line 91, in wrapper
    return function(*args, **kwargs)
           ^^^^^^^^^^^^^^^^^^^^^^^^^
  File "/home/airflow/.local/lib/python3.12/site-packages/polars/_utils/deprecation.py", line 91, in wrapper
    return function(*args, **kwargs)
           ^^^^^^^^^^^^^^^^^^^^^^^^^
  File "/home/airflow/.local/lib/python3.12/site-packages/polars/io/csv/functions.py", line 500, in read_csv
    df = _read_csv_impl(
         ^^^^^^^^^^^^^^^
  File "/home/airflow/.local/lib/python3.12/site-packages/polars/io/csv/functions.py", line 646, in _read_csv_impl
    pydf = PyDataFrame.read_csv(
           ^^^^^^^^^^^^^^^^^^^^^
polars.exceptions.ComputeError: could not parse `personal_number` as dtype `i64` at column 'personal_number' (column number 4)

The current offset in the file is 1281255 bytes.

You might want to try:
- increasing `infer_schema_length` (e.g. `infer_schema_length=10000`),
- specifying correct dtype with the `dtypes` argument
- setting `ignore_errors` to `True`,
- adding `personal_number` to the `null_values` list.

Original error: ```remaining bytes non-empty```
[2025-07-08T05:15:58.349+0000] {local_task_job_runner.py:266} INFO - Task exited with return code 1
[2025-07-08T05:15:58.409+0000] {taskinstance.py:3900} INFO - 0 downstream tasks scheduled from follow-on schedule check
[2025-07-08T05:15:58.418+0000] {local_task_job_runner.py:245} INFO - ::endgroup::
