[2025-07-08T05:19:41.135+0000] {local_task_job_runner.py:123} INFO - ::group::Pre task execution logs
[2025-07-08T05:19:41.187+0000] {taskinstance.py:2612} INFO - Dependencies all met for dep_context=non-requeueable deps ti=<TaskInstance: extract_raw_data_pipeline.load_raw_data manual__2025-07-08T05:19:09.727248+00:00 [queued]>
[2025-07-08T05:19:41.210+0000] {taskinstance.py:2612} INFO - Dependencies all met for dep_context=requeueable deps ti=<TaskInstance: extract_raw_data_pipeline.load_raw_data manual__2025-07-08T05:19:09.727248+00:00 [queued]>
[2025-07-08T05:19:41.211+0000] {taskinstance.py:2865} INFO - Starting attempt 1 of 1
[2025-07-08T05:19:41.248+0000] {taskinstance.py:2888} INFO - Executing <Task(SQLExecuteQueryOperator): load_raw_data> on 2025-07-08 05:19:09.727248+00:00
[2025-07-08T05:19:41.268+0000] {warnings.py:112} WARNING - /home/***/.local/lib/python3.12/site-packages/***/task/task_runner/standard_task_runner.py:70: DeprecationWarning: This process (pid=720) is multi-threaded, use of fork() may lead to deadlocks in the child.
  pid = os.fork()

[2025-07-08T05:19:41.272+0000] {standard_task_runner.py:72} INFO - Started process 722 to run task
[2025-07-08T05:19:41.273+0000] {standard_task_runner.py:104} INFO - Running: ['***', 'tasks', 'run', 'extract_raw_data_pipeline', 'load_raw_data', 'manual__2025-07-08T05:19:09.727248+00:00', '--job-id', '35', '--raw', '--subdir', 'DAGS_FOLDER/driven_data_pipeline.py', '--cfg-path', '/tmp/tmpa3jp9onx']
[2025-07-08T05:19:41.275+0000] {standard_task_runner.py:105} INFO - Job 35: Subtask load_raw_data
[2025-07-08T05:19:41.425+0000] {task_command.py:467} INFO - Running <TaskInstance: extract_raw_data_pipeline.load_raw_data manual__2025-07-08T05:19:09.727248+00:00 [running]> on host 5e24963c1987
[2025-07-08T05:19:41.711+0000] {taskinstance.py:3131} INFO - Exporting env vars: AIRFLOW_CTX_DAG_OWNER='***' AIRFLOW_CTX_DAG_ID='extract_raw_data_pipeline' AIRFLOW_CTX_TASK_ID='load_raw_data' AIRFLOW_CTX_EXECUTION_DATE='2025-07-08T05:19:09.727248+00:00' AIRFLOW_CTX_TRY_NUMBER='1' AIRFLOW_CTX_DAG_RUN_ID='manual__2025-07-08T05:19:09.727248+00:00'
[2025-07-08T05:19:41.714+0000] {taskinstance.py:731} INFO - ::endgroup::
[2025-07-08T05:19:41.748+0000] {sql.py:266} INFO - Executing: 
    COPY driven_raw.raw_batch_data(
    person_name, user_name, email, personal_number, birth_date,
    address, phone, mac_address, ip_address, iban, accessed_at,
    session_duration, download_speed, upload_speed, consumed_traffic, unique_id
    )
    FROM '/opt/***/data/raw_data.csv'
    DELIMITER ','
    CSV HEADER;
    
[2025-07-08T05:19:41.770+0000] {base.py:84} INFO - Retrieving connection 'postgres_conn'
[2025-07-08T05:19:41.790+0000] {base.py:84} INFO - Retrieving connection 'postgres_conn'
[2025-07-08T05:19:41.802+0000] {sql.py:509} INFO - Running statement: 
    COPY driven_raw.raw_batch_data(
    person_name, user_name, email, personal_number, birth_date,
    address, phone, mac_address, ip_address, iban, accessed_at,
    session_duration, download_speed, upload_speed, consumed_traffic, unique_id
    )
    FROM '/opt/***/data/raw_data.csv'
    DELIMITER ','
    CSV HEADER;
    , parameters: None
[2025-07-08T05:19:41.835+0000] {taskinstance.py:3310} ERROR - Task failed with exception
Traceback (most recent call last):
  File "/home/airflow/.local/lib/python3.12/site-packages/airflow/models/taskinstance.py", line 767, in _execute_task
    result = _execute_callable(context=context, **execute_callable_kwargs)
             ^^^^^^^^^^^^^^^^^^^^^^^^^^^^^^^^^^^^^^^^^^^^^^^^^^^^^^^^^^^^^
  File "/home/airflow/.local/lib/python3.12/site-packages/airflow/models/taskinstance.py", line 733, in _execute_callable
    return ExecutionCallableRunner(
           ^^^^^^^^^^^^^^^^^^^^^^^^
  File "/home/airflow/.local/lib/python3.12/site-packages/airflow/utils/operator_helpers.py", line 252, in run
    return self.func(*args, **kwargs)
           ^^^^^^^^^^^^^^^^^^^^^^^^^^
  File "/home/airflow/.local/lib/python3.12/site-packages/airflow/models/baseoperator.py", line 406, in wrapper
    return func(self, *args, **kwargs)
           ^^^^^^^^^^^^^^^^^^^^^^^^^^^
  File "/home/airflow/.local/lib/python3.12/site-packages/airflow/providers/common/sql/operators/sql.py", line 272, in execute
    output = hook.run(
             ^^^^^^^^^
  File "/home/airflow/.local/lib/python3.12/site-packages/airflow/providers/common/sql/hooks/sql.py", line 456, in run
    self._run_command(cur, sql_statement, parameters)
  File "/home/airflow/.local/lib/python3.12/site-packages/airflow/providers/common/sql/hooks/sql.py", line 514, in _run_command
    cur.execute(sql_statement)
psycopg2.errors.InvalidTextRepresentation: invalid input syntax for type numeric: "personal_number"
CONTEXT:  COPY raw_batch_data, line 842, column personal_number: "personal_number"

[2025-07-08T05:19:41.863+0000] {taskinstance.py:1225} INFO - Marking task as FAILED. dag_id=extract_raw_data_pipeline, task_id=load_raw_data, run_id=manual__2025-07-08T05:19:09.727248+00:00, execution_date=20250708T051909, start_date=20250708T051941, end_date=20250708T051941
[2025-07-08T05:19:41.889+0000] {taskinstance.py:340} INFO - ::group::Post task execution logs
[2025-07-08T05:19:41.890+0000] {standard_task_runner.py:124} ERROR - Failed to execute job 35 for task load_raw_data (invalid input syntax for type numeric: "personal_number"
CONTEXT:  COPY raw_batch_data, line 842, column personal_number: "personal_number"
; 722)
Traceback (most recent call last):
  File "/home/airflow/.local/lib/python3.12/site-packages/airflow/task/task_runner/standard_task_runner.py", line 117, in _start_by_fork
    ret = args.func(args, dag=self.dag)
          ^^^^^^^^^^^^^^^^^^^^^^^^^^^^^
  File "/home/airflow/.local/lib/python3.12/site-packages/airflow/cli/cli_config.py", line 49, in command
    return func(*args, **kwargs)
           ^^^^^^^^^^^^^^^^^^^^^
  File "/home/airflow/.local/lib/python3.12/site-packages/airflow/utils/cli.py", line 115, in wrapper
    return f(*args, **kwargs)
           ^^^^^^^^^^^^^^^^^^
  File "/home/airflow/.local/lib/python3.12/site-packages/airflow/cli/commands/task_command.py", line 483, in task_run
    task_return_code = _run_task_by_selected_method(args, _dag, ti)
                       ^^^^^^^^^^^^^^^^^^^^^^^^^^^^^^^^^^^^^^^^^^^^
  File "/home/airflow/.local/lib/python3.12/site-packages/airflow/cli/commands/task_command.py", line 256, in _run_task_by_selected_method
    return _run_raw_task(args, ti)
           ^^^^^^^^^^^^^^^^^^^^^^^
  File "/home/airflow/.local/lib/python3.12/site-packages/airflow/cli/commands/task_command.py", line 341, in _run_raw_task
    return ti._run_raw_task(
           ^^^^^^^^^^^^^^^^^
  File "/home/airflow/.local/lib/python3.12/site-packages/airflow/utils/session.py", line 97, in wrapper
    return func(*args, session=session, **kwargs)
           ^^^^^^^^^^^^^^^^^^^^^^^^^^^^^^^^^^^^^^
  File "/home/airflow/.local/lib/python3.12/site-packages/airflow/models/taskinstance.py", line 3004, in _run_raw_task
    return _run_raw_task(
           ^^^^^^^^^^^^^^
  File "/home/airflow/.local/lib/python3.12/site-packages/airflow/models/taskinstance.py", line 273, in _run_raw_task
    TaskInstance._execute_task_with_callbacks(
  File "/home/airflow/.local/lib/python3.12/site-packages/airflow/models/taskinstance.py", line 3158, in _execute_task_with_callbacks
    result = self._execute_task(context, task_orig)
             ^^^^^^^^^^^^^^^^^^^^^^^^^^^^^^^^^^^^^^
  File "/home/airflow/.local/lib/python3.12/site-packages/airflow/models/taskinstance.py", line 3182, in _execute_task
    return _execute_task(self, context, task_orig)
           ^^^^^^^^^^^^^^^^^^^^^^^^^^^^^^^^^^^^^^^
  File "/home/airflow/.local/lib/python3.12/site-packages/airflow/models/taskinstance.py", line 767, in _execute_task
    result = _execute_callable(context=context, **execute_callable_kwargs)
             ^^^^^^^^^^^^^^^^^^^^^^^^^^^^^^^^^^^^^^^^^^^^^^^^^^^^^^^^^^^^^
  File "/home/airflow/.local/lib/python3.12/site-packages/airflow/models/taskinstance.py", line 733, in _execute_callable
    return ExecutionCallableRunner(
           ^^^^^^^^^^^^^^^^^^^^^^^^
  File "/home/airflow/.local/lib/python3.12/site-packages/airflow/utils/operator_helpers.py", line 252, in run
    return self.func(*args, **kwargs)
           ^^^^^^^^^^^^^^^^^^^^^^^^^^
  File "/home/airflow/.local/lib/python3.12/site-packages/airflow/models/baseoperator.py", line 406, in wrapper
    return func(self, *args, **kwargs)
           ^^^^^^^^^^^^^^^^^^^^^^^^^^^
  File "/home/airflow/.local/lib/python3.12/site-packages/airflow/providers/common/sql/operators/sql.py", line 272, in execute
    output = hook.run(
             ^^^^^^^^^
  File "/home/airflow/.local/lib/python3.12/site-packages/airflow/providers/common/sql/hooks/sql.py", line 456, in run
    self._run_command(cur, sql_statement, parameters)
  File "/home/airflow/.local/lib/python3.12/site-packages/airflow/providers/common/sql/hooks/sql.py", line 514, in _run_command
    cur.execute(sql_statement)
psycopg2.errors.InvalidTextRepresentation: invalid input syntax for type numeric: "personal_number"
CONTEXT:  COPY raw_batch_data, line 842, column personal_number: "personal_number"

[2025-07-08T05:19:41.935+0000] {local_task_job_runner.py:266} INFO - Task exited with return code 1
[2025-07-08T05:19:42.002+0000] {taskinstance.py:3900} INFO - 0 downstream tasks scheduled from follow-on schedule check
[2025-07-08T05:19:42.013+0000] {local_task_job_runner.py:245} INFO - ::endgroup::
