[2025-07-02T08:58:36.007+0000] {local_task_job_runner.py:123} INFO - ::group::Pre task execution logs
[2025-07-02T08:58:36.826+0000] {taskinstance.py:2612} INFO - Dependencies all met for dep_context=non-requeueable deps ti=<TaskInstance: extract_raw_data_pipeline.extract_raw_data manual__2025-07-02T08:58:24.982157+00:00 [queued]>
[2025-07-02T08:58:36.912+0000] {taskinstance.py:2612} INFO - Dependencies all met for dep_context=requeueable deps ti=<TaskInstance: extract_raw_data_pipeline.extract_raw_data manual__2025-07-02T08:58:24.982157+00:00 [queued]>
[2025-07-02T08:58:36.923+0000] {taskinstance.py:2865} INFO - Starting attempt 1 of 1
[2025-07-02T08:58:37.112+0000] {taskinstance.py:2888} INFO - Executing <Task(PythonOperator): extract_raw_data> on 2025-07-02 08:58:24.982157+00:00
[2025-07-02T08:58:37.266+0000] {standard_task_runner.py:104} INFO - Running: ['***', 'tasks', 'run', 'extract_raw_data_pipeline', 'extract_raw_data', 'manual__2025-07-02T08:58:24.982157+00:00', '--job-id', '10', '--raw', '--subdir', 'DAGS_FOLDER/driven_data_pipeline.py', '--cfg-path', '/tmp/tmpq0bwc396']
[2025-07-02T08:58:37.244+0000] {warnings.py:112} WARNING - /home/***/.local/lib/python3.12/site-packages/***/task/task_runner/standard_task_runner.py:70: DeprecationWarning: This process (pid=826) is multi-threaded, use of fork() may lead to deadlocks in the child.
  pid = os.fork()

[2025-07-02T08:58:37.285+0000] {standard_task_runner.py:105} INFO - Job 10: Subtask extract_raw_data
[2025-07-02T08:58:37.290+0000] {standard_task_runner.py:72} INFO - Started process 829 to run task
[2025-07-02T08:58:38.321+0000] {task_command.py:467} INFO - Running <TaskInstance: extract_raw_data_pipeline.extract_raw_data manual__2025-07-02T08:58:24.982157+00:00 [running]> on host 5e24963c1987
[2025-07-02T08:58:40.675+0000] {taskinstance.py:3131} INFO - Exporting env vars: AIRFLOW_CTX_DAG_OWNER='***' AIRFLOW_CTX_DAG_ID='extract_raw_data_pipeline' AIRFLOW_CTX_TASK_ID='extract_raw_data' AIRFLOW_CTX_EXECUTION_DATE='2025-07-02T08:58:24.982157+00:00' AIRFLOW_CTX_TRY_NUMBER='1' AIRFLOW_CTX_DAG_RUN_ID='manual__2025-07-02T08:58:24.982157+00:00'
[2025-07-02T08:58:40.695+0000] {taskinstance.py:731} INFO - ::endgroup::
[2025-07-02T08:58:40.925+0000] {driven_data_pipeline.py:143} INFO - Started batch processing for 2025-07-02.
[2025-07-02T08:58:40.931+0000] {driven_data_pipeline.py:34} INFO - Created synthetic data for RO country code.
[2025-07-02T09:01:58.653+0000] {job.py:239} ERROR - Job heartbeat failed with error
Traceback (most recent call last):
  File "/home/airflow/.local/lib/python3.12/site-packages/sqlalchemy/engine/base.py", line 3371, in _wrap_pool_connect
    return fn()
           ^^^^
  File "/home/airflow/.local/lib/python3.12/site-packages/sqlalchemy/pool/base.py", line 327, in connect
    return _ConnectionFairy._checkout(self)
           ^^^^^^^^^^^^^^^^^^^^^^^^^^^^^^^^
  File "/home/airflow/.local/lib/python3.12/site-packages/sqlalchemy/pool/base.py", line 894, in _checkout
    fairy = _ConnectionRecord.checkout(pool)
            ^^^^^^^^^^^^^^^^^^^^^^^^^^^^^^^^
  File "/home/airflow/.local/lib/python3.12/site-packages/sqlalchemy/pool/base.py", line 493, in checkout
    rec = pool._do_get()
          ^^^^^^^^^^^^^^
  File "/home/airflow/.local/lib/python3.12/site-packages/sqlalchemy/pool/impl.py", line 256, in _do_get
    return self._create_connection()
           ^^^^^^^^^^^^^^^^^^^^^^^^^
  File "/home/airflow/.local/lib/python3.12/site-packages/sqlalchemy/pool/base.py", line 273, in _create_connection
    return _ConnectionRecord(self)
           ^^^^^^^^^^^^^^^^^^^^^^^
  File "/home/airflow/.local/lib/python3.12/site-packages/sqlalchemy/pool/base.py", line 388, in __init__
    self.__connect()
  File "/home/airflow/.local/lib/python3.12/site-packages/sqlalchemy/pool/base.py", line 690, in __connect
    with util.safe_reraise():
         ^^^^^^^^^^^^^^^^^^^
  File "/home/airflow/.local/lib/python3.12/site-packages/sqlalchemy/util/langhelpers.py", line 70, in __exit__
    compat.raise_(
  File "/home/airflow/.local/lib/python3.12/site-packages/sqlalchemy/util/compat.py", line 211, in raise_
    raise exception
  File "/home/airflow/.local/lib/python3.12/site-packages/sqlalchemy/pool/base.py", line 686, in __connect
    self.dbapi_connection = connection = pool._invoke_creator(self)
                                         ^^^^^^^^^^^^^^^^^^^^^^^^^^
  File "/home/airflow/.local/lib/python3.12/site-packages/sqlalchemy/engine/create.py", line 574, in connect
    return dialect.connect(*cargs, **cparams)
           ^^^^^^^^^^^^^^^^^^^^^^^^^^^^^^^^^^
  File "/home/airflow/.local/lib/python3.12/site-packages/sqlalchemy/engine/default.py", line 598, in connect
    return self.dbapi.connect(*cargs, **cparams)
           ^^^^^^^^^^^^^^^^^^^^^^^^^^^^^^^^^^^^^
  File "/home/airflow/.local/lib/python3.12/site-packages/psycopg2/__init__.py", line 122, in connect
    conn = _connect(dsn, connection_factory=connection_factory, **kwasync)
           ^^^^^^^^^^^^^^^^^^^^^^^^^^^^^^^^^^^^^^^^^^^^^^^^^^^^^^^^^^^^^^^
psycopg2.OperationalError: could not translate host name "postgres" to address: Temporary failure in name resolution


The above exception was the direct cause of the following exception:

Traceback (most recent call last):
  File "/home/airflow/.local/lib/python3.12/site-packages/airflow/jobs/job.py", line 233, in heartbeat
    heartbeat_callback(session)
  File "/home/airflow/.local/lib/python3.12/site-packages/airflow/utils/session.py", line 94, in wrapper
    return func(*args, **kwargs)
           ^^^^^^^^^^^^^^^^^^^^^
  File "/home/airflow/.local/lib/python3.12/site-packages/airflow/jobs/local_task_job_runner.py", line 284, in heartbeat_callback
    self.task_instance.refresh_from_db()
  File "/home/airflow/.local/lib/python3.12/site-packages/airflow/utils/session.py", line 97, in wrapper
    return func(*args, session=session, **kwargs)
           ^^^^^^^^^^^^^^^^^^^^^^^^^^^^^^^^^^^^^^
  File "/home/airflow/.local/lib/python3.12/site-packages/airflow/models/taskinstance.py", line 2358, in refresh_from_db
    _refresh_from_db(task_instance=self, session=session, lock_for_update=lock_for_update)
  File "/home/airflow/.local/lib/python3.12/site-packages/airflow/models/taskinstance.py", line 872, in _refresh_from_db
    ti = TaskInstance.get_task_instance(
         ^^^^^^^^^^^^^^^^^^^^^^^^^^^^^^^
  File "/home/airflow/.local/lib/python3.12/site-packages/airflow/api_internal/internal_api_call.py", line 139, in wrapper
    return func(*args, **kwargs)
           ^^^^^^^^^^^^^^^^^^^^^
  File "/home/airflow/.local/lib/python3.12/site-packages/airflow/utils/session.py", line 94, in wrapper
    return func(*args, **kwargs)
           ^^^^^^^^^^^^^^^^^^^^^
  File "/home/airflow/.local/lib/python3.12/site-packages/airflow/models/taskinstance.py", line 2344, in get_task_instance
    return query.one_or_none()
           ^^^^^^^^^^^^^^^^^^^
  File "/home/airflow/.local/lib/python3.12/site-packages/sqlalchemy/orm/query.py", line 2850, in one_or_none
    return self._iter().one_or_none()
           ^^^^^^^^^^^^
  File "/home/airflow/.local/lib/python3.12/site-packages/sqlalchemy/orm/query.py", line 2916, in _iter
    result = self.session.execute(
             ^^^^^^^^^^^^^^^^^^^^^
  File "/home/airflow/.local/lib/python3.12/site-packages/sqlalchemy/orm/session.py", line 1716, in execute
    conn = self._connection_for_bind(bind)
           ^^^^^^^^^^^^^^^^^^^^^^^^^^^^^^^
  File "/home/airflow/.local/lib/python3.12/site-packages/sqlalchemy/orm/session.py", line 1555, in _connection_for_bind
    return self._transaction._connection_for_bind(
           ^^^^^^^^^^^^^^^^^^^^^^^^^^^^^^^^^^^^^^^
  File "/home/airflow/.local/lib/python3.12/site-packages/sqlalchemy/orm/session.py", line 750, in _connection_for_bind
    conn = bind.connect()
           ^^^^^^^^^^^^^^
  File "/home/airflow/.local/lib/python3.12/site-packages/sqlalchemy/future/engine.py", line 412, in connect
    return super(Engine, self).connect()
           ^^^^^^^^^^^^^^^^^^^^^^^^^^^^^
  File "/home/airflow/.local/lib/python3.12/site-packages/sqlalchemy/engine/base.py", line 3325, in connect
    return self._connection_cls(self, close_with_result=close_with_result)
           ^^^^^^^^^^^^^^^^^^^^^^^^^^^^^^^^^^^^^^^^^^^^^^^^^^^^^^^^^^^^^^^
  File "/home/airflow/.local/lib/python3.12/site-packages/sqlalchemy/engine/base.py", line 96, in __init__
    else engine.raw_connection()
         ^^^^^^^^^^^^^^^^^^^^^^^
  File "/home/airflow/.local/lib/python3.12/site-packages/sqlalchemy/engine/base.py", line 3404, in raw_connection
    return self._wrap_pool_connect(self.pool.connect, _connection)
           ^^^^^^^^^^^^^^^^^^^^^^^^^^^^^^^^^^^^^^^^^^^^^^^^^^^^^^^
  File "/home/airflow/.local/lib/python3.12/site-packages/sqlalchemy/engine/base.py", line 3374, in _wrap_pool_connect
    Connection._handle_dbapi_exception_noconnection(
  File "/home/airflow/.local/lib/python3.12/site-packages/sqlalchemy/engine/base.py", line 2208, in _handle_dbapi_exception_noconnection
    util.raise_(
  File "/home/airflow/.local/lib/python3.12/site-packages/sqlalchemy/util/compat.py", line 211, in raise_
    raise exception
  File "/home/airflow/.local/lib/python3.12/site-packages/sqlalchemy/engine/base.py", line 3371, in _wrap_pool_connect
    return fn()
           ^^^^
  File "/home/airflow/.local/lib/python3.12/site-packages/sqlalchemy/pool/base.py", line 327, in connect
    return _ConnectionFairy._checkout(self)
           ^^^^^^^^^^^^^^^^^^^^^^^^^^^^^^^^
  File "/home/airflow/.local/lib/python3.12/site-packages/sqlalchemy/pool/base.py", line 894, in _checkout
    fairy = _ConnectionRecord.checkout(pool)
            ^^^^^^^^^^^^^^^^^^^^^^^^^^^^^^^^
  File "/home/airflow/.local/lib/python3.12/site-packages/sqlalchemy/pool/base.py", line 493, in checkout
    rec = pool._do_get()
          ^^^^^^^^^^^^^^
  File "/home/airflow/.local/lib/python3.12/site-packages/sqlalchemy/pool/impl.py", line 256, in _do_get
    return self._create_connection()
           ^^^^^^^^^^^^^^^^^^^^^^^^^
  File "/home/airflow/.local/lib/python3.12/site-packages/sqlalchemy/pool/base.py", line 273, in _create_connection
    return _ConnectionRecord(self)
           ^^^^^^^^^^^^^^^^^^^^^^^
  File "/home/airflow/.local/lib/python3.12/site-packages/sqlalchemy/pool/base.py", line 388, in __init__
    self.__connect()
  File "/home/airflow/.local/lib/python3.12/site-packages/sqlalchemy/pool/base.py", line 690, in __connect
    with util.safe_reraise():
         ^^^^^^^^^^^^^^^^^^^
  File "/home/airflow/.local/lib/python3.12/site-packages/sqlalchemy/util/langhelpers.py", line 70, in __exit__
    compat.raise_(
  File "/home/airflow/.local/lib/python3.12/site-packages/sqlalchemy/util/compat.py", line 211, in raise_
    raise exception
  File "/home/airflow/.local/lib/python3.12/site-packages/sqlalchemy/pool/base.py", line 686, in __connect
    self.dbapi_connection = connection = pool._invoke_creator(self)
                                         ^^^^^^^^^^^^^^^^^^^^^^^^^^
  File "/home/airflow/.local/lib/python3.12/site-packages/sqlalchemy/engine/create.py", line 574, in connect
    return dialect.connect(*cargs, **cparams)
           ^^^^^^^^^^^^^^^^^^^^^^^^^^^^^^^^^^
  File "/home/airflow/.local/lib/python3.12/site-packages/sqlalchemy/engine/default.py", line 598, in connect
    return self.dbapi.connect(*cargs, **cparams)
           ^^^^^^^^^^^^^^^^^^^^^^^^^^^^^^^^^^^^^
  File "/home/airflow/.local/lib/python3.12/site-packages/psycopg2/__init__.py", line 122, in connect
    conn = _connect(dsn, connection_factory=connection_factory, **kwasync)
           ^^^^^^^^^^^^^^^^^^^^^^^^^^^^^^^^^^^^^^^^^^^^^^^^^^^^^^^^^^^^^^^
sqlalchemy.exc.OperationalError: (psycopg2.OperationalError) could not translate host name "postgres" to address: Temporary failure in name resolution

(Background on this error at: https://sqlalche.me/e/14/e3q8)
[2025-07-02T09:03:06.524+0000] {job.py:254} ERROR - Job heartbeat failed with error. Scheduler is in unhealthy state
[2025-07-02T09:03:09.443+0000] {driven_data_pipeline.py:100} INFO - Written 840 records to the CSV file.
[2025-07-02T09:03:12.775+0000] {job.py:229} INFO - Heartbeat recovered after 268.85 seconds
[2025-07-02T09:03:14.526+0000] {driven_data_pipeline.py:116} INFO - Added UUID to the dataset.
[2025-07-02T09:03:15.218+0000] {driven_data_pipeline.py:135} INFO - Updated accessed timestamp.
[2025-07-02T09:03:15.228+0000] {driven_data_pipeline.py:151} INFO - Finished batch processing 2025-07-02.
[2025-07-02T09:03:15.271+0000] {python.py:240} INFO - Done. Returned value was: None
[2025-07-02T09:03:18.426+0000] {taskinstance.py:340} INFO - ::group::Post task execution logs
[2025-07-02T09:03:18.522+0000] {taskinstance.py:352} INFO - Marking task as SUCCESS. dag_id=extract_raw_data_pipeline, task_id=extract_raw_data, run_id=manual__2025-07-02T08:58:24.982157+00:00, execution_date=20250702T085824, start_date=20250702T085836, end_date=20250702T090318
[2025-07-02T09:03:20.134+0000] {local_task_job_runner.py:266} INFO - Task exited with return code 0
[2025-07-02T09:03:22.288+0000] {taskinstance.py:3900} INFO - 0 downstream tasks scheduled from follow-on schedule check
[2025-07-02T09:03:22.409+0000] {local_task_job_runner.py:245} INFO - ::endgroup::
[2025-07-02T09:03:22.985+0000] {standard_task_runner.py:217} INFO - Process not found (most likely exited), stop collecting metrics
